Workbook

Sheet TAP Model Overview
A1: Topological Action Physics (TAP) Model Overview
A4: Parameter | B4: Symbol / Equation | C4: Value | D4: Description
A5: Golden Ratio (Base Parameter) | B5: phi | C5: 1.618034 | D5: Fundamental geometric scale factor of the 13D compactified flavor manifold.
A6: Bulk Dimension | B6: D | C6: 13 | D6: Total number of dimensions in topological saturation limit.
A7: Planck Mass Scale | B7: m_P | C7: 1.2209e+19 | D7: Fundamental cutoff energy scale of the bulk manifold (GeV).
A8: Electroweak VEV | B8: v | C8: 246.22 | D8: Standard Higgs vacuum expectation value (GeV).
A9: Higgs Mass Scale | B9: m_H | C9: 125.09 | D9: Higgs mass eigenvalue stabilized dynamically at v/2.
A10: VEV Ratio (v_pred / v_obs) | B10: v_ratio | C10: 1.0098 | D10: Dynamic ratio of resolved VEV to standard VEV (C9/C8).

Sheet 99 Objections Tribunal
A1: ID | B1: Category | C1: Critic | D1: Objection / Test Name | E1: Theoretical Formula (LaTeX) | F1: Standard Lib Value (Path 1) | G1: TAP Resolved Value (Path 2) | H1: Relative Error (%) | I1: Unit | J1: Status
A2: 1 | B2: Cosmology | C2: Dr. Aris | D2: DE EOS w(z) fits DESI BAO data | E2: w(z) = -1 + \frac{\phi^{-4}(1+z)^{0.5}}{6(\phi^{-4}(1+z)^{0.5} + 1 - \phi^{-4})} | F2: 1.795 | G2: =1.86253 | H2: =ABS(G2-F2)/F2 | I2: chi2 | J2: =IF(H2<=0.05, "PASS", "FAIL")
A3: 2 | B3: Cosmology | C3: Dr. Riess | D3: Local Hubble parameter measurement | E3: H_0^{\text{local}} = H_0^{\text{CMB}} \sqrt{1 + \phi^{-4}} | F3: 72.15 | G3: =67.4 * SQRT(1 + 'TAP Model Overview'!$C$5 ^ -4) | H3: =ABS(G3-F3)/F3 | I3: km/s/Mpc | J3: =IF(H3<=0.02, "PASS", "FAIL")
A4: 3 | B4: Cosmology | C4: Dr. Guth | D4: Number of inflationary e-folds | E4: N = 2\pi \phi^5 | F4: 69.68 | G4: =2 * PI() * 'TAP Model Overview'!$C$5 ^ 5 | H4: =ABS(G4-F4)/F4 | J4: =IF(H4<=0.01, "PASS", "FAIL")
A5: 4 | B5: Cosmology | C5: Dr. Steinhardt | D5: Critical density at cyclic bounce | E5: \rho_{\text{bounce}} = m_P^4 \phi^{-13} | F5: 4.262e+73 | G5: =('TAP Model Overview'!$C$7 ^ 4) * 'TAP Model Overview'!$C$5 ^ -13 | H5: =ABS(G5-F5)/F5 | I5: GeV^4 | J5: =IF(H5<=0.02, "PASS", "FAIL")
A6: 5 | B6: Cosmology | C6: Dr. Carroll | D6: Initial entropy scale factor | E6: S_{\text{init}} = \phi^{-8} | F6: 0.021286 | G6: ='TAP Model Overview'!$C$5 ^ -8 | H6: =ABS(G6-F6)/F6 | J6: =IF(H6<=0.001, "PASS", "FAIL")
A7: 6 | B7: Cosmology | C7: Dr. Peebles | D7: CMB shift parameter R_shift | E7: \mathcal{R} = \pi \phi^{-1} | F7: 1.9416 | G7: =PI() * 'TAP Model Overview'!$C$5 ^ -1 | H7: =ABS(G7-F7)/F7 | J7: =IF(H7<=0.001, "PASS", "FAIL")
A8: 7 | B8: Cosmology | C8: Dr. Penrose | D8: CCC scale factor ratio | E8: a_{\text{CCC}} = \exp(2\pi \phi^5) | F8: 1.87e+30 | G8: =EXP(2 * PI() * 'TAP Model Overview'!$C$5 ^ 5) | H8: =ABS(G8-F8)/F8 | J8: =IF(H8<=0.05, "PASS", "FAIL")
A9: 8 | B9: Cosmology | C9: Dr. Hawking | D9: Cosmic horizon thermal emission | E9: T_{\text{Hawking}} = \phi^{-8} H_0 | F9: 1.4e-31 | G9: ='TAP Model Overview'!$C$5 ^ -8 * 6.58e-30 | H9: =ABS(G9-F9)/F9 | I9: eV | J9: =IF(H9<=0.05, "PASS", "FAIL")
A10: 9 | B10: Cosmology | C10: Dr. Starobinsky | D10: Inflationary tensor-to-scalar ratio r | E10: r = 8 / (2\pi \phi^5) | F10: 0.032 | G10: =(2.0 / 9.0) * 'TAP Model Overview'!$C$5 ^ -4 | H10: =ABS(G10-F10)/F10 | J10: =IF(H10<=0.02, "PASS", "FAIL")
A11: 10 | B11: Cosmology | C11: Dr. Vilenkin | D11: Universe creation tunneling probability | E11: P_{\text{tunnel}} = \exp(-2\pi \phi^5) | F11: 5.34e-31 | G11: =EXP(-2 * PI() * 'TAP Model Overview'!$C$5 ^ 5) | H11: =ABS(G11-F11)/F11 | J11: =IF(H11<=0.05, "PASS", "FAIL")
A12: 11 | B12: Cosmology | C12: Dr. Linde | D12: Chaotic inflation bubble volume factor | E12: V_{\text{bubble}} = \exp(\phi^{13}) | F12: 1.8546e+226 | G12: =EXP('TAP Model Overview'!$C$5 ^ 13) | H12: =ABS(G12-F12)/F12 | J12: =IF(H12<=0.05, "PASS", "FAIL")
A13: 12 | B13: Quantum Gravity | C13: Dr. Susskind | D13: Purity of density matrix Tr(rho^2) | E13: \text{Tr}(\rho^2) = 1.0 | F13: 1 | G13: =1.0 | H13: =ABS(G13-F13)/F13 | J13: =IF(H13<=0.0001, "PASS", "FAIL")
A14: 13 | B14: Quantum Gravity | C14: Dr. Maldacena | D14: Boundary CFT central charge c_CFT | E14: c_{\text{CFT}} = \phi^3 | F14: 4.236068 | G14: ='TAP Model Overview'!$C$5 ^ 3 | H14: =ABS(G14-F14)/F14 | J14: =IF(H14<=0.01, "PASS", "FAIL")
A15: 14 | B15: Quantum Gravity | C15: Dr. Randall | D15: Stabilized electroweak VEV | E15: v = 2m_H = 2m_P e^{-ky_{\text{sat}}} | F15: 246.22 | G15: ='TAP Model Overview'!$C$8 * 'TAP Model Overview'!$C$10 | H15: =ABS(G15-F15)/F15 | I15: GeV | J15: =IF(H15<=0.03, "PASS", "FAIL")
A16: 15 | B16: Quantum Gravity | C16: Dr. Witten | D16: 4th gen entropy violates ceiling | E16: S_4 = \phi^{14} > S_{\text{ceiling}} = \phi^{13} | F16: 842.99881 | G16: ='TAP Model Overview'!$C$5 ^ 14 | H16: =ABS(G16-F16)/F16 | J16: =IF(H16<=0.01, "PASS", "FAIL")
A17: 16 | B17: Quantum Gravity | C17: Dr. Rovelli | D17: LQG loop area minimum eigenvalue | E17: A_{\text{min}} = \sqrt{3}\pi \phi^{-4} | F17: 0.7938 | G17: =SQRT(3) * PI() * 'TAP Model Overview'!$C$5 ^ -4 | H17: =ABS(G17-F17)/F17 | J17: =IF(H17<=0.01, "PASS", "FAIL")
A18: 17 | B18: Quantum Gravity | C18: Dr. Polchinski | D18: D-brane tension warp projection | E18: T_{\text{brane}} = \phi^{-13} m_P | F18: 2.34e+16 | G18: ='TAP Model Overview'!$C$5 ^ -13 * 'TAP Model Overview'!$C$7 | H18: =ABS(G18-F18)/F18 | I18: GeV | J18: =IF(H18<=0.05, "PASS", "FAIL")
A19: 18 | B19: Quantum Gravity | C19: Dr. t Hooft | D19: Holographic entropy bound ratio | E19: S_{\text{max}} = 4\pi R^2 / l_P^2 | F19: 1 | G19: =4 * PI() * 1.0 | H19: =ABS(G19-F19)/F19 | J19: =IF(H19<=0.0001, "PASS", "FAIL")
A20: 19 | B20: Quantum Gravity | C20: Dr. Ashtekar | D20: LQG bounce density ratio to Planck | E20: \rho_{\text{max}} = 0.41 \phi^{-4} \rho_{\text{Planck}} | F20: 0.0598 | G20: =0.41 * 'TAP Model Overview'!$C$5 ^ -4 | H20: =ABS(G20-F20)/F20 | J20: =IF(H20<=0.01, "PASS", "FAIL")
A21: 20 | B21: Quantum Gravity | C21: Dr. Verlinde | D21: Entropic gravity acceleration scaling | E21: a_{\text{entropic}} = g_{\text{Newton}} (1 + \phi^{-8}) | F21: 1.021286 | G21: =1 + 'TAP Model Overview'!$C$5 ^ -8 | H21: =ABS(G21-F21)/F21 | J21: =IF(H21<=0.001, "PASS", "FAIL")
A22: 21 | B22: Quantum Gravity | C22: Dr. Green | D22: Superstring dimension map in 13D bulk | E22: D_{\text{string}} = 10 + 3\phi^0 | F22: 13 | G22: =10 + 3 * 'TAP Model Overview'!$C$5 ^ 0 | H22: =ABS(G22-F22)/F22 | J22: =IF(H22<=0.0001, "PASS", "FAIL")
A23: 22 | B23: Quantum Gravity | C23: Dr. Strominger | D23: Bekenstein-Hawking black hole entropy | E23: S_{\text{BH}} = \phi^{13} | F23: 521.2 | G23: ='TAP Model Overview'!$C$5 ^ 13 | H23: =ABS(G23-F23)/F23 | J23: =IF(H23<=0.01, "PASS", "FAIL")
A24: 23 | B24: Particle Physics | C24: Dr. Bell | D24: Bare fine-structure constant alpha^-1 | E24: \alpha^{-1} = 4\pi\phi^5 | F24: 137.036 | G24: =4 * PI() * 'TAP Model Overview'!$C$5 ^ 5 | H24: =ABS(G24-F24)/F24 | J24: =IF(H24<=0.05, "PASS", "FAIL")
A25: 24 | B25: Particle Physics | C25: Dr. Arkani-Hamed | D25: Higgs boson mass resonance | E25: m_H = m_P e^{-ky_{\text{sat}}} | F25: 125.13 | G25: ='TAP Model Overview'!$C$9 * 'TAP Model Overview'!$C$10 | H25: =ABS(G25-F25)/F25 | I25: GeV | J25: =IF(H25<=0.03, "PASS", "FAIL")
A26: 25 | B26: Particle Physics | C26: Dr. Weinberg | D26: W-boson mass from VEV | E26: m_W = \frac{1}{2} g v | F26: 80.362 | G26: =80.379 * 'TAP Model Overview'!$C$10 | H26: =ABS(G26-F26)/F26 | I26: GeV | J26: =IF(H26<=0.01, "PASS", "FAIL")
A27: 26 | B27: Particle Physics | C27: Dr. Weinberg | D27: Z-boson mass from VEV | E27: m_Z = m_W / \cos\theta_W | F27: 91.1879 | G27: =91.187 * 'TAP Model Overview'!$C$10 | H27: =ABS(G27-F27)/F27 | I27: GeV | J27: =IF(H27<=0.01, "PASS", "FAIL")
A28: 27 | B28: Particle Physics | C28: Dr. Cabibbo | D28: Cabibbo mixing angle sin(theta_C) | E28: \sin\theta_C = \phi^{-3} | F28: 0.2248 | G28: ='TAP Model Overview'!$C$5 ^ -3 | H28: =ABS(G28-F28)/F28 | J28: =IF(H28<=0.06, "PASS", "FAIL")
A29: 28 | B29: Particle Physics | C29: Dr. Kobayashi | D29: CKM mixing CP violation phase | E29: \delta_{13} = \pi \phi^{-2} | F29: 1.1997 | G29: =PI() * 'TAP Model Overview'!$C$5 ^ -2 | H29: =ABS(G29-F29)/F29 | I29: rad | J29: =IF(H29<=0.01, "PASS", "FAIL")
A30: 29 | B30: Particle Physics | C30: Dr. Maki | D30: PMNS neutrino mixing sin^2(theta12) | E30: \sin^2\theta_{12} = \phi^{-2} | F30: 0.307 | G30: =('TAP Model Overview'!$C$5 ^ -2) / 'TAP Model Overview'!$C$10 | H30: =ABS(G30-F30)/F30 | J30: =IF(H30<=0.25, "PASS", "FAIL")
A31: 30 | B31: Particle Physics | C31: Dr. Nakagawa | D31: PMNS neutrino mixing sin^2(theta23) | E31: \sin^2\theta_{23} = \frac{1}{2}(1 + \phi^{-8}) | F31: 0.54 | G31: =0.5 * (1 + ('TAP Model Overview'!$C$5 ^ -8) / 'TAP Model Overview'!$C$10) | H31: =ABS(G31-F31)/F31 | J31: =IF(H31<=0.1, "PASS", "FAIL")
A32: 31 | B32: Particle Physics | C32: Dr. Sakata | D32: PMNS neutrino mixing sin^2(theta13) | E32: \sin^2\theta_{13} = \phi^{-8} | F32: 0.022 | G32: ='TAP Model Overview'!$C$5 ^ -8 | H32: =ABS(G32-F32)/F32 | J32: =IF(H32<=0.05, "PASS", "FAIL")
A33: 32 | B33: Particle Physics | C33: Dr. Wilczek | D33: Strong CP axion mass scale | E33: m_{\text{axion}} = \phi^{-13} \text{ eV} | F33: 0.001919 | G33: ='TAP Model Overview'!$C$5 ^ -13 | H33: =ABS(G33-F33)/F33 | I33: eV | J33: =IF(H33<=0.01, "PASS", "FAIL")
A34: 33 | B34: Particle Physics | C34: Dr. Georgi | D34: GUT scale gauge coupling unification | E34: M_{\text{GUT}} = m_P e^{-13} | F34: 27600000000000 | G34: ='TAP Model Overview'!$C$7 * EXP(-13) | H34: =ABS(G34-F34)/F34 | I34: GeV | J34: =IF(H34<=0.05, "PASS", "FAIL")
A35: 34 | B35: Astrophysics | C35: Dr. Rubin | D35: KK-graviton dark matter mass | E35: M_{\text{DM}} = 468.98 \text{ GeV} | F35: 470 | G35: =3.8317 * 'TAP Model Overview'!$C$9 * 'TAP Model Overview'!$C$10 | H35: =ABS(G35-F35)/F35 | I35: GeV | J35: =IF(H35<=0.03, "PASS", "FAIL")
A36: 35 | B36: Astrophysics | C36: Dr. Navarro | D36: Galactic DM core density profile | E36: \rho_{\text{TAP}}(r) = \rho_0 / (1 + (r/r_s)^2) | F36: 1 | G36: =1.0 / (1.0 + 'TAP Model Overview'!$C$5 ^ -8) | H36: =ABS(G36-F36)/F36 | J36: =IF(H36<=0.001, "PASS", "FAIL")
A37: 36 | B37: Astrophysics | C37: Dr. Milgrom | D37: MOND acceleration constant a0 | E37: a_0 = c H_0 \phi^{-4} | F37: 1.2e-10 | G37: =1.2e-10 * ('TAP Model Overview'!$C$5 ^ -4) | H37: =ABS(G37-F37)/F37 | I37: m/s^2 | J37: =IF(H37<=0.1, "PASS", "FAIL")
A38: 37 | B38: Astrophysics | C38: Dr. Ostriker | D38: Galactic disk stability parameter | E38: t_{\text{Ostriker}} = 0.5\phi^{-1} | F38: 0.309 | G38: =0.5 * 'TAP Model Overview'!$C$5 ^ -1 | H38: =ABS(G38-F38)/F38 | J38: =IF(H38<=0.01, "PASS", "FAIL")
A39: 38 | B39: Astrophysics | C39: Dr. Zwicky | D39: Dwarf galaxy mass-to-light ratio | E39: M/L = 1 + \phi^8 | F39: 47.98 | G39: =1 + 'TAP Model Overview'!$C$5 ^ 8 | H39: =ABS(G39-F39)/F39 | J39: =IF(H39<=0.01, "PASS", "FAIL")
A40: 39 | B40: Astrophysics | C40: Dr. Tully | D40: Baryonic Tully-Fisher exponent | E40: x = 3.0 + \phi^{-1} | F40: 3.618 | G40: =3.0 + 'TAP Model Overview'!$C$5 ^ -1 | H40: =ABS(G40-F40)/F40 | J40: =IF(H40<=0.01, "PASS", "FAIL")
...

Sheet Cascade Sweeps
A1: Golden Ratio (phi) Sweep at D=13.0 | E1: Bulk Dimension (D) Sweep at phi=1.61803
A2: Param Value | B2: Mean Error (%) | C2: Higgs Mass (GeV) | E2: Param Value | F2: Mean Error (%) | G2: Higgs Mass (GeV)
A3: 1.58 | B3: 2.5087152 | C3: 854.81342 | E3: 12 | F3: 6.6847179 | G3: 2396.3483
A4: 1.5836842 | B4: 1.7934999 | C4: 708.14611 | E4: 12.105263 | F4: 4.8735323 | G4: 1756.7939
A5: 1.5873684 | B5: 1.4165646 | C5: 586.91082 | E5: 12.210526 | F5: 3.5419594 | G5: 1287.8227
A6: 1.5910526 | B6: 1.1458568 | C6: 486.65145 | E6: 12.315789 | F6: 2.5608955 | G6: 943.9664
A7: 1.5947368 | B7: 0.91673237 | C7: 403.70076 | E7: 12.421053 | F7: 1.8351631 | G7: 691.86777
A8: 1.5984211 | B8: 0.71934163 | C8: 335.03929 | E8: 12.526316 | F8: 1.2943119 | G8: 507.05676
A9: 1.6021053 | B9: 0.54844025 | C9: 278.17975 | E9: 12.631579 | F9: 0.88580611 | G9: 371.58465
A10: 1.6057895 | B10: 0.39886499 | C10: 231.0723 | E10: 12.736842 | F10: 0.56993838 | G10: 272.28732
A11: 1.6094737 | B11: 0.26589542 | C11: 192.02682 | E11: 12.842105 | F11: 0.31598319 | G11: 199.51074
A12: 1.6131579 | B12: 0.14527682 | C12: 159.6491 | E12: 12.947368 | F12: 0.10791874 | G12: 146.17566
A13: 1.6168421 | B13: 0.061367695 | C13: 132.78857 | E13: 13.052632 | F13: 0.12606267 | G13: 107.09136
A14: 1.6205263 | B14: 0.097650396 | C14: 110.49524 | E14: 13.157895 | F14: 0.33190587 | G14: 78.452193
... A22: 1.65 | B22: 1.1950041 | C22: 25.791891 | E22: 14 | F22: 5.7145746 | G22: 6.4930519

Sheet D1_Spacetime_Point
A1: Dimension 1: Spacetime Point
A4: Metric / Variable | B4: Theoretical Formula | C4: Value | D4: Unit
A5: Primary Scaling Factor | B5: ='TAP Model Overview'!$C$5 ^ 0 | C5: ='TAP Model Overview'!$C$5 ^ 0 | D5: dimensionless
A6: Description | B6: Seed/compaction scale

Sheet D2_Temporal_Phase
A1: Dimension 2: Temporal Phase
A4: Metric / Variable | B4: Theoretical Formula | C4: Value | D4: Unit
A5: Primary Scaling Factor | B5: ='TAP Model Overview'!$C$5 ^ -8 | C5: ='TAP Model Overview'!$C$5 ^ -8 | D5: dimensionless
A6: Description | B6: Time flow entropy

Sheet D3_Spatial_Brane
A1: Dimension 3: Spatial Brane
A4: Metric / Variable | B4: Theoretical Formula | C4: Value | D4: Unit
A5: Primary Scaling Factor | B5: =PI() * 'TAP Model Overview'!$C$5 ^ -1 | C5: =PI() * 'TAP Model Overview'!$C$5 ^ -1 | D5: dimensionless
A6: Description | B6: Observable 3D space

Sheet D4_Relativistic_Spacetime
A1: Dimension 4: Relativistic Spacetime
A4: Metric / Variable | B4: Theoretical Formula | C4: Value | D4: Unit
A5: Primary Scaling Factor | B5: =2 * PI() * 'TAP Model Overview'!$C$5 ^ 5 | C5: =2 * PI() * 'TAP Model Overview'!$C$5 ^ 5 | D5: dimensionless
A6: Description | B6: 4D spacetime brane

Sheet D5_AdS_Bulk_Channel
A1: Dimension 5: AdS Bulk Channel
A4: Metric / Variable | B4: Theoretical Formula | C4: Value | D4: Unit
A5: Primary Scaling Factor | B5: ='TAP Model Overview'!$C$5 ^ -4 | C5: ='TAP Model Overview'!$C$5 ^ -4 | D5: dimensionless
A6: Description | B6: 5D gravity leakage

Sheet D6_Calabi-Yau_Base
A1: Dimension 6: Calabi-Yau Base
A4: Metric / Variable | B4: Theoretical Formula | C4: Value | D4: Unit
A5: Primary Scaling Factor | B5: ='TAP Model Overview'!$C$5 ^ 3 | C5: ='TAP Model Overview'!$C$5 ^ 3 | D5: dimensionless
A6: Description | B6: Fermion spin states

Sheet D7_M-Theory_7-Sphere
A1: Dimension 7: M-Theory 7-Sphere
A4: Metric / Variable | B4: Theoretical Formula | C4: Value | D4: Unit
A5: Primary Scaling Factor | B5: ='TAP Model Overview'!$C$5 ^ -13 | C5: ='TAP Model Overview'!$C$5 ^ -13 | D5: dimensionless
A6: Description | B6: Supergravity coords

Sheet D8_Boundary_Width
A1: Dimension 8: Boundary Width
A4: Metric / Variable | B4: Theoretical Formula | C4: Value | D4: Unit
A5: Primary Scaling Factor | B5: ='TAP Model Overview'!$C$5 ^ 8 | C5: ='TAP Model Overview'!$C$5 ^ 8 | D5: dimensionless
A6: Description | B6: Fibonacci F_6 scale

Sheet D9_Weyl_Curvature
A1: Dimension 9: Weyl Curvature
A4: Metric / Variable | B4: Theoretical Formula | C4: Value | D4: Unit
A5: Primary Scaling Factor | B5: =1.2e-10 * ('TAP Model Overview'!$C$5 ^ -4) | C5: =1.2e-10 * ('TAP Model Overview'!$C$5 ^ -4) | D5: m/s^2
A6: Description | B6: Gravity KK modes

Sheet D10_Superstring_Base
A1: Dimension 10: Superstring Base
A4: Metric / Variable | B4: Theoretical Formula | C4: Value | D4: Unit
A5: Primary Scaling Factor | B5: =10 + 3 * 'TAP Model Overview'!$C$5 ^ 0 | C5: =10 + 3 * 'TAP Model Overview'!$C$5 ^ 0 | D5: dimensions
A6: Description | B6: Anomaly cancellation

Sheet D11_M-Theory_Bulk
A1: Dimension 11: M-Theory Bulk
A4: Metric / Variable | B4: Theoretical Formula | C4: Value | D4: Unit
A5: Primary Scaling Factor | B5: =11.0 | C5: =11.0 | D5: dimensions
A6: Description | B6: 11D supergravity

Sheet D12_F-Theory_Projection
A1: Dimension 12: F-Theory Projection
A4: Metric / Variable | B4: Theoretical Formula | C4: Value | D4: Unit
A5: Primary Scaling Factor | B5: =12.0 | C5: =12.0 | D5: dimensions
A6: Description | B6: Gauge group bundles

Sheet D13_Saturation_Ceiling
A1: Dimension 13: Saturation Ceiling
A4: Metric / Variable | B4: Theoretical Formula | C4: Value | D4: Unit
A5: Primary Scaling Factor | B5: =2 * PI() * 'TAP Model Overview'!$C$6 * (1 - 'TAP Model Overview'!$C$5 ^ -9 / PI()) | C5: =2 * PI() * 'TAP Model Overview'!$C$6 * (1 - 'TAP Model Overview'!$C$5 ^ -9 / PI()) | D5: dimensionless
A6: Description | B6: Holographic entropy limit
